Workbook
Name AnalysisTerm: 'Initial Screens'!$C$14
Name Growth: 'ROI Results'!$I$8
Name Hardware_Refreshcylce: 'ROI Results'!$F$53
Name Hosts: 'Initial Screens'!$C$17
Name Inflation: 'ROI Results'!$I$9
Name VMs: 'Initial Screens'!$C$16

Sheet Initial Screens
B2: Private Cloud Maturity & Optimization (PCMO) Tool | E2: any values in yellow input cells for illustration only | G2: Cell Color Legend
B3: Layout should be aligned with PCMO | G3: Input | I3: must be input
G4: Overridable default | I4: Can be edited
B5: PCMO Get Started Screen | G5: Data pull | I5: Can't be edited
G6: Calculation | I6: Can't be edited
B7: Customer Name | C7: Acme Company | G7: Data ingestion or overridable default | I7: Can't be edited if data ingested from collector tool (RV Tools, Live Optics)
B8: Analysis Data Industry | C8: Financial Services | D8: <-- Note to Mediafly: Default should be blank | G8: red notes | H8: comments for MediaFly or internal
B9: Analysis Data Region | C9: AMER | D9: <-- Note to Mediafly: Default should be blank
B11: Value Model Configuration | D11: <-- This "screen" follows when Value Model is included
B13: Future state solution | C13: VCF 9
B14: Term of analysis | C14: 10
B16: Number of VMs | C16: 5000
B17: Number of VM Hosts | C17: 400
B18: Average allocated/provisioned storage (GBs) per VM | C18: 300 | H18: vSAN storage = VMs x avg allocated GBs per VM
G19: Traditional storage only used for TCO Assessment
B20: Component Usage | C20: Current State | D20: Future State
B21: % of Operations coverage | C21: 0 | D21: 1
A22: =IF(ISNUMBER(SEARCH("VCF",$C$13)),"Show","Hide") -> Show | B22: % of Automation coverage | C22: 0 | D22: =IF(A22="Show",100%,0) -> 1
A23: =$A$22 -> Show | B23: % Of NSX coverage | C23: 0 | D23: 1
A24: =IF($C$13="VVF","Hide","Show") -> Show | B24: % of vSAN Coverage | C24: 0 | D24: 1
B26: Select Advanced Services: | C26: Avi Load Balancer | D26: No
A27: =$A$22 -> Show | C27: vDefend Distributed Firewall | D27: No
C28: Data Services Manager (DSM) | D28: No | E28: =IF(D28="Yes","","Must include DSM for any Public Native Cloud comparison") -> Must include DSM for any Public Native Cloud comparison
C29: VMware Live Recovery (VLR) | D29: No

Sheet Notes
B2: For MediaFly
B4: Cell Color Legend
B5: Input | D5: must be input
B6: Overridable default | D6: Can be edited
B7: Data pull | D7: Can't be edited
B8: Calculation | D8: Can't be edited
B9: red notes | C9: comments for MediaFly or internal
B12: Internal
B14: V2.5 Items
A15: x | B15: VLR simplified
A16: x | B16: Custom Benefits for Software Cost Savings and Labor Productivity
A17: x | B17: VVF jump start
A18: x | B18: add P2V
A19: x | B19: Sustainability
A20: x | B20: Growth & Inflation
B21: Past Value Analysis - see separate workbook
B23: Time permitting
B24: Rounding
B25: Fully Q&A for consistency & errors

Sheet Excel Output
B2: TCO & ROI Analysis Workbook | I2: Cell Color Legend
I3: Overridable default | K3: Can be edited
B4: Customer | C4: ='Initial Screens'!C7 -> Acme Company | I4: Data pull | K4: Generally should not be edited
B5: Date | C5: =NOW() -> 45982.798 | H5: Date of download | I5: Calculation | K5: Shouldn't be edited
B6: Term of Analysis | C6: =AnalysisTerm&"-Year Term" -> 10-Year Term
B7: VMware Solution | C7: Vmware Cloud Foundation
B9: Workbook Contents
B10: Intro
B11: This workbook provides value analysis output for transparency of math regarding data used and assumptions made for estimating the financial value of moving to VCF.
B12: Analysis Tabs
B13: Tabs include the ablity to create bottoms up calculations for current state and future state costs related to Compute, Storage, Network, Software, Labor, Migration, and Reskilling.
B14: In addition Business Impact in the form of profits related to increased or protected revenue and risk reduction based on reduced downtime and security incidents can be assessed.
B15: Results Tab
B16: ROI Summary - provides key financial metrics and a summary of multi-year benefit and investment calculations, based on the benefits analyzed and assumed value realization assumptions.
B18: Some Data Used
B19: Initial data inputs
B20: ='Initial Screens'!B14 -> Term of analysis | D20: =AnalysisTerm -> 10
B22: ='Initial Screens'!B16 -> Number of VMs | D22: ='Initial Screens'!C16 -> 5000 | H22: for Excel output, these values should drive the rest of the output sheets
B23: ='Initial Screens'!B17 -> Number of VM Hosts | D23: ='Initial Screens'!C17 -> 400 | H23: for Excel output, these values should drive the rest of the output sheets
B24: ='Initial Screens'!B18 -> Average allocated/provisioned storage (GBs) per VM | D24: ='Initial Screens'!C18 -> 300 | H24: for Excel output, these values should drive the rest of the output sheets
B26: ='Initial Screens'!B20 -> Component Usage | D26: ='Initial Screens'!C20 -> Current State | E26: ='Initial Screens'!D20 -> Future State
B27: ='Initial Screens'!B21 -> % of Operations coverage | D27: ='Initial Screens'!C21 -> 0 | E27: ='Initial Screens'!D21 -> 1 | H27: for Excel output, these values should drive the rest of the output sheets
A28: ='Initial Screens'!$A$22 -> Show | B28: ='Initial Screens'!B22 -> % of Automation coverage | D28: ='Initial Screens'!C22 -> 0 | E28: =IF(A28="Hide",D28,'Initial Screens'!D22) -> 1 | H28: for Excel output, these values should drive the rest of the output sheets
A29: ='Initial Screens'!$A$22 -> Show | B29: ='Initial Screens'!B23 -> % Of NSX coverage | D29: ='Initial Screens'!C23 -> 0 | E29: =IF(A29="Hide",D29,'Initial Screens'!D23) -> 1 | H29: for Excel output, these values should drive the rest of the output sheets
A30: =IF('Initial Screens'!$C$13="VVF","Hide","Show") -> Show | B30: ='Initial Screens'!B24 -> % of vSAN Coverage | D30: ='Initial Screens'!C24 -> 0 | E30: =IF(A30="Hide",D30,'Initial Screens'!D24) -> 1 | H30: for Excel output, these values should drive the rest of the output sheets
B32: TCO Results Overview
B34: CURRENT STATE | E34: FUTURE STATE
B35: Products | C35: ="vSphere"&IF('Excel Output'!D27>0,", VCF Operations","")&IF('Excel Output'!D28>0,", VCF Automation","")&IF('Excel Output'!D29>0,", NSX","")&IF('Excel Output'!D30>0,", vSAN","") -> vSphere | E35: Products | F35: =IF('Initial Screens'!C13="VCF","VMware Cloud Foundation"&IF('Initial Screens'!D26="Yes",", Avi Load Balancer","")&IF('Initial Screens'!D27="yes",", vDefend Firewall","")&IF('Initial Screens'!D28="yes",", Data Services Manager","")&IF('Initial Screens'!D29="yes",", VMware Live Recovery",""),IF('Initial Screens'!C13="VVF","VMware vSphere Foundation","VMware vSphere Foundation, vSAN")) -> VMware vSphere Foundation, vSAN
B36: Host Architecture | C36: =FIXED(Compute!D40,0)&" CPUs, "&FIXED(Compute!D41,0)&" Cores, "&FIXED(Compute!D42,0)&" GB RAM per Host" -> 2 CPUs, 36 Cores, 768 GB RAM per Host | E36: Host Architecture | F36: =FIXED(Compute!F40,0)&" CPUs, "&FIXED(Compute!F41,0)&" Cores, "&FIXED(Compute!F42,0)&" GB RAM per Host" -> 2 CPUs, 48 Cores, 1,024 GB RAM per Host
B37: License Type | C37: SnS related to perpetual or subscription | E37: License Type | F37: Subscription
B39: ='Initial Screens'!C14&" Year Total TCO" -> 10 Year Total TCO | C39: =SUM(C45:C53) -> 2.1468287e+08 | E39: =B39 -> 10 Year Total TCO | F39: =SUM(F45:F53) -> 1.2261756e+08
E40: $ Savings over Current | F40: =C39-F39 -> 92065311
E41: % Savings over Current | F41: =F40/C39 -> 0.42884331
E42: % ROI over Current | F42: ='ROI Results'!E9 -> 9.75
B44: Cost Categories | E44: =FIXED(D20,0)&"-Year VCF Migration and Adoption Future State" -> 10-Year VCF Migration and Adoption Future State
B45: Compute | C45: ='ROI Results'!O71 -> 61914772 | D45: worksheet | E45: Compute | F45: ='ROI Results'!O85 -> 27627724
B46: Storage | C46: ='ROI Results'!O72 -> 25461120 | D46: worksheet | E46: Storage | F46: ='ROI Results'!O86 -> 9458613.3
B47: Network | C47: ='ROI Results'!O73 -> 6166095.6 | D47: worksheet | E47: Network | F47: ='ROI Results'!O87 -> 2743020.3
B48: Software | C48: ='ROI Results'!O74 -> 6288946.3 | D48: worksheet | E48: Software | F48: ='ROI Results'!O88 -> 8881408
B49: Facilities | C49: ='ROI Results'!O75 -> 37336277 | D49: worksheet | E49: Facilities | F49: ='ROI Results'!O89 -> 21605405
...

Sheet Compute
B2: Current State Compute Costs & Anticipated Reduction | G2: Return button
B4: Current State | H4: Sourcing & Comments
B5: Number of VMs | F5: ='Excel Output'!D22 -> 5000
B6: Number of VM Hosts | F6: ='Excel Output'!$D$23 -> 400
B7: VMs/Host | F7: =F5/F6 -> 12.5 | H7: Calculation
A8: =IF('Initial Screens'!$C$13="VVF","Hide","Show") -> Show | B8: Percent of Hosts that are vSAN ready nodes | F8: =IF('Initial Screens'!C13="VVF",0,'Excel Output'!D30) -> 0
A9: =IF($F$8=100%,"Hide","Show") -> Show | B9: Average purchase cost per current state ESXi host | F9: =IF(F8=1,0,25000) -> 25000 | H9: Placeholder default
A10: =IF($F$8=0,"Hide","Show") -> Hide | B10: Average purchase cost per current state vSAN ready node | F10: =IF(F8>0,35000,0) -> 0 | H10: Placeholder default
B11: Annual compute hardware support | F11: 0.15 | H11: Placeholder default
B12: =FIXED(AnalysisTerm,0)&"-Year Current State Cost" -> 10-Year Current State Cost | F12: =(ROUND(F6*(1-F8),0)*F9+ROUND(F6*F8,0)*F10)*(1+AnalysisTerm*F11) -> 25000000 | H12: Calculation
B13: Future State
B14: Percent of VMs to be decommissioned (including reduction via containerization of applications) | F14: =IF('Excel Output'!E28>'Excel Output'!D28,10%,5%) -> 0.1 | H14: Conservative default estimate; The Forrester Total Economic Impact™ Of VMware vRealize Automation (2019) indicated as high as 50% per year
B15: Number of VMs on premises | F15: =ROUND(F$5*(1-F$14),0) -> 4500 | H15: Calculation
A16: =IF('Initial Screens'!$C$13="VVF","Hide","Show") -> Show | B16: Percent of Hosts that will be vSAN ready nodes | F16: ='Excel Output'!E30 -> 1 | H16: From Inputs | P16: OLD | Q16: OLD | R16: NEW | S16: NEW
B17: =IF('Initial Screens'!$C$13="VVF","Number of VM Hosts","Number of VM Hosts (vSAN Ready Nodes and ESXi Hosts)") -> Number of VM Hosts (vSAN Ready Nodes and ESXi Hosts) | F17: =F46 -> 143 | H17: From worksheet below | M17: Component Usage | N17: Current State | O17: Future State | P17: CPU Utilization | Q17: RAM Utilization | R17: CPU Utilization | S17: RAM Utilization
B18: VMs/Host | F18: =F15/F17 -> 31.468531 | H18: Calculation | L18: Scenario 1 | M18: % of Operations coverage | N18: 0 | O18: 1 | P18: 0.3 | Q18: 0.45873786 | R18: 0.35 | S18: 0.45873786
A19: =IF($F$16=0%,"Hide","Show") -> Show | B19: Number of vSAN Ready Nodes | F19: =ROUND(F16*F17,0) -> 143 | G19: Worksheet | H19: Calculation | L19: Scenario 1 | M19: % of Automation coverage | N19: 0 | O19: 1
A20: =IF($F$16=100%,"Hide","Show") -> Hide | B20: Number of ESXi Hosts | F20: =ROUND(F17*(1-F16),0) -> 0 | G20: Worksheet | H20: Calculation | L20: Scenario 1 | M20: % Of NSX coverage | N20: 0 | O20: 1
A21: =IF($F$16=0%,"Hide","Show") -> Show | B21: Average compute cost (excludes storage component) per vSAN Ready Node | F21: =IF(F16=0,0,C65) -> 25000 | G21: Worksheet | H21: Calculation below | L21: Scenario 1 | M21: % of vSAN Coverage | N21: 0 | O21: 1
A22: =IF($F$16=100%,"Hide","Show") -> Hide | B22: Average purchase cost per host (ESXi Hosts) | F22: =IF(F16=1,0,F9) -> 0 | H22: Pull from above | L22: Scenario 2 | M22: % of Operations coverage | N22: 0 | O22: 1 | P22: 0.3 | Q22: 0.40909091 | R22: 0.3125 | S22: 0.40909091
B23: Annual compute hardware support | F23: 0.15 | H23: Placeholder estimate | L23: Scenario 2 | M23: % of Automation coverage | N23: 0 | O23: 1
B24: =FIXED(AnalysisTerm,0)&"-Year Future State Cost" -> 10-Year Future State Cost | F24: =ROUND(F19*F21+F20*F22,0)*(1+AnalysisTerm*F23) -> 8937500 | H24: Calculation | L24: Scenario 2 | M24: % Of NSX coverage | N24: 0.5 | O24: 1
L25: Scenario 2 | M25: % of vSAN Coverage | N25: 0 | O25: 1
B26: Target VM Host Sizing | L26: Scenario 3 | M26: % of Operations coverage | N26: 0.5 | O26: 1 | P26: 0.3125 | Q26: 0.40909091 | R26: 0.3 | S26: 0.40909091
A28: =IF('Initial Screens'!C13="VCF 9","Show","hide") -> Show | B28: Include Memory Tiering benefits | D28: =IF(A28="show","Yes","No") -> Yes | H28: Advanced Memory Management and Scheduling, with DPM :VCF delivers better resource management through its memory overcommitment and memory oversubscription features leading to improved host consolidation
A29: =IF(D28="No","hide","show") -> show | B29: Anticipated percentage improvement in CPU overcommit (vCPU:pCPU) due to additional Memory capacity | D29: =IF(D28="Yes",20%,0%) -> 0.2
A30: =$A$29 -> show | B30: Anticipated percentage improvement in Memory overcommit | D30: =IF(D28="Yes",5%,0%) -> 0.05 | G30: =(50%-D43)/(2+IF('Excel Output'!E27=0,2,0)+IF('Excel Output'!E29=0,2,0))*SUM(Misc!E136,Misc!E138)/2 -> 0.15
G31: =G30*(1+D29) -> 0.18 | L31: Scenario 3 | M31: % of Automation coverage | N31: 0.5 | O31: 1
B32: VM Profile | D32: Current State | F32: Future State | H32: Sourcing and Comments | L32: Scenario 3 | M32: % Of NSX coverage | N32: 0 | O32: 1
B33: Number of VMs (on premises) | D33: =F5 -> 5000 | F33: =F15 -> 4500 | H33: =H5 -> 0 | L33: Scenario 3 | M33: % of vSAN Coverage | N33: 0 | O33: 1
B34: Total Storage requirement per VM(GB) | D34: ='Excel Output'!D24 -> 300 | F34: =D34 -> 300 | H34: ='Initial Screens'!$E$18 -> 0 | L34: Scenario 4 | M34: % of Operations coverage | N34: 0.5 | O34: 1 | P34: 0.3 | Q34: 0.40909091 | R34: 0.3125 | S34: 0.40909091
B35: vCPUs per VM | D35: 2 | F35: =D35 -> 2 | H35: Placeholder default | J35: Pull current state from Data Ingestion when used | L35: Scenario 4 | M35: % of Automation coverage | N35: 0 | O35: 1
B36: GB RAM per VM | D36: 4 | F36: =D36 -> 4 | H36: Placeholder default | J36: Pull current state from Data Ingestion when used | L36: Scenario 4 | M36: % Of NSX coverage | N36: 0 | O36: 1
B37: vCPU to core ratio | D37: 4 | F37: =D37 -> 4 | H37: Placeholder default | J37: Pull current state from Data Ingestion when used | L37: Scenario 4 | M37: % of vSAN Coverage | N37: 0 | O37: 1
B38: On Premises VM Host Profile | L38: Scenario 4 | M38: % of Operations coverage | N38: 0 | O38: 1 | P38: 0.3 | Q38: 0.45873786 | R38: 0.35 | S38: 0.45873786
B39: Number of Hosts | D39: =F6 -> 400 | H39: ='Initial Screens'!$E$17 -> 0 | L39: Scenario 4 | M39: % of Automation coverage | N39: 0.5 | O39: 1
B40: CPUs (Sockets) per host | D40: =ROUND(2,0) -> 2 | F40: 2 | G40: =48-F41 -> 0 | H40: Placeholder default | L40: Scenario 4 | M40: % Of NSX coverage | N40: 0 | O40: 1
B41: Total Cores per Host | D41: 36 | F41: =IF('Initial Screens'!$C$13="VCF",MAX(48,D41),D41)+12 -> 48 | H41: Placeholder default | J41: Pull current state from Data Ingestion when used | L41: Scenario 4 | M41: % of vSAN Coverage | N41: 0 | O41: 1
B42: RAM (GB)/host server | D42: =ROUND(768,0) -> 768 | F42: =IF(ISNUMBER(SEARCH("VCF",'Initial Screens'!$C$13)),MAX(1024,D42),D42) -> 1024 | H42: Placeholder default | J42: Pull current state from Data Ingestion when used
B43: CPU Utilization | D43: 0.2 | F43: =IF(ISNUMBER(SEARCH("VCF",'Initial Screens'!$C$13)),D43+(50%-D43)/(2+IF('Excel Output'!E27=0,2,0)+IF('Excel Output'!E29=0,2,0))*SUM(Misc!E136,Misc!E138)/2*(1+D29),D43+1%) -> 0.38 | H43: Placeholder default | J43: Pull current state from Data Ingestion when used
...

Sheet Storage
B2: Current State Storage Costs & Anticipated Reduction | G2: Return button
B4: Current State | H4: Sourcing & Comments
B5: Number of VMs | F5: ='Excel Output'!D22 -> 5000 | H5: From inputs
A6: =IF(Compute!$D$68="No","Hide","Show") -> Show | B6: Number of Physical legacy servers | F6: =Compute!F73 -> 0 | H6: From Compute
B7: Average allocated/provisioned storage (GBs) per VM | F7: ='Excel Output'!D24 -> 300
A8: =IF(Compute!$D$68="No","Hide","Show") -> Show | B8: Average allocated/provisioned storage (GBs) per Physical Server | F8: =IF(Compute!D68="No",0,'Excel Output'!D24) -> 300 | G8: =IF(Compute!D68="No","leave blank","") | H8: Placeholder default
B9: Total GBs of allocated/provisioned storage to support VMs | F9: =ROUND(F5*F7+F6*F8,0) -> 1500000 | H9: Calculation
B10: Usable to Raw Ratio | F10: 0.7 | H10: Placeholder estimate - Ratio of Usable storage to Raw capacity. The raw capacity includes storage requirement for RAID/FTT levels, swap space, dedupe, compression and other file and system overheads
B11: Total Raw Capacity required to support VMs (GB) | F11: =ROUND(F9/F10,0) -> 2142857 | H11: Calculation
A12: =IF('Initial Screens'!$C$13="VVF","Hide","Show") -> Show | B12: Percent of Hosts that are vSAN ready nodes | F12: =Compute!F8 -> 0 | H12: From inputs
A13: =IF($F$12=100%,"Hide","Show") -> Show | B13: Upfront external storage purchase cost per GB | F13: 2 | H13: Placeholder estimate
A14: =IF($F$12=0%,"Hide","Show") -> Hide | B14: Upfront capacity disk based storage cost per GB | F14: =F26 -> 0.98 | H14: From worksheet
B15: Other Storage Devices (includes SAN switches, HBAs etc.) as % of Host Cost | F15: 0.05 | H15: Placeholder estimate - Includes FC SAN switches and HBA/SFP interconnects
B16: Number of VM Hosts | F16: ='Excel Output'!D23 -> 400 | H16: ='Initial Screens'!$E$17 -> 0
B17: Average purchase cost per current state VM host | F17: =Compute!F8*Compute!F10+(1-Compute!F8)*Compute!F9 -> 25000 | H17: Calculation
A18: =IF(Compute!$D$68="No","Hide","Show") -> Show | B18: Average purchase cost per physical legacy server | F18: =Compute!F74 -> 5000 | H18: From Compute
B19: Other Storage Devices Cost | F19: =ROUND(F15*(F16*F17+F6*F18),0) -> 500000 | H19: Calculation
B20: Annual storage hardware support | F20: 0.15 | H20: Placeholder default
B21: =FIXED(AnalysisTerm,0)&"-Year Current State Cost" -> 10-Year Current State Cost | F21: =ROUND(Storage!F11*Storage!F12*Storage!F14+Storage!F11*(1-Storage!F12)*Storage!F13+Storage!F19,0)*(1+AnalysisTerm*Storage!F20) -> 11964285 | H21: Calculation
B22: Future State
B23: Number of VMs | F23: =ROUND(SUM(Compute!F15),0) -> 4500 | H23: Calculation
B24: Usable to Raw Ratio | F24: =IF('Initial Screens'!$C$13="VVF",F10,C47) -> 1.125 | G24: Worksheet | H24: From Worksheet
B25: Total Raw Capacity required to support VMs (GB) | F25: =ROUND(F23*F7*'Initial Screens'!D24/F24+F23*F7*(1-'Initial Screens'!D24)/Storage!F10,0) -> 1200000 | H25: Calculation based on the vSAN coverage
A26: =IF($F$29>0,"Show","Hide") -> Show | B26: Upfront storage purchase cost per GB with vSAN | F26: =C66 -> 0.98 | G26: Worksheet | H26: From Worksheet
A27: =IF($F$30>0,"Show","Hide") -> Hide | B27: Upfront storage purchase cost per GB without vSAN | F27: =F13 -> 2 | H27: Placeholder estimate
A28: =IF($F$30>0,"Show","Hide") -> Hide | B28: =B15 -> Other Storage Devices (includes SAN switches, HBAs etc.) as % of Host Cost | F28: =F15 -> 0.05 | H28: From above
A29: =IF($F$29>0,"Show","Hide") -> Show | B29: Number of vSAN Ready Nodes | F29: =Compute!F19 -> 143 | H29: From Compute
A30: =IF($F$30>0,"Show","Hide") -> Hide | B30: Number of ESXi Hosts | F30: =Compute!F20 -> 0 | H30: From Compute
A31: =IF($F$30>0,"Show","Hide") -> Hide | B31: Average purchase cost per host (ESXi Hosts) | F31: =Compute!F9 -> 25000 | H31: This is the server compute cost, embedded storage cost is factored under storage costs
A32: =IF($F$30>0,"Show","Hide") -> Hide | B32: Other Storage Devices Cost | F32: =F28*F30*F31 -> 0 | H32: Calculation
B33: Annual storage hardware support | F33: 0.15 | H33: Placeholder default
B34: =FIXED(AnalysisTerm,0)&"-Year Future State Cost" -> 10-Year Future State Cost | F34: =ROUND(F25*F26*Compute!F16+F25*(1-Compute!F16)*F27+F32,0)*(1+AnalysisTerm*F33) -> 2940000 | H34: Calculation
A36: =IF('Initial Screens'!$C$13="VVF","Hide","Show") -> Show | B36: Usable to Raw Ratio (Assumes ESA vSAN Architecture)
A37: =IF('Initial Screens'!$C$13="VVF","Hide","Show") -> Show
A38: =IF('Initial Screens'!$C$13="VVF","Hide","Show") -> Show | B38: Usable to Raw Ratio Calculation | H38: Sourcing and Comments
A39: =IF('Initial Screens'!$C$13="VVF","Hide","Show") -> Show | B39: Capacity Disk Size (GB) | C39: 1920 | D39: <--note to MF, this value should be bidirectionally linked with value in the worksheet below | H39: Placeholder estimate
A40: =IF('Initial Screens'!$C$13="VVF","Hide","Show") -> Show | B40: Operation Reserve Percentage | C40: =ROUND(25%,3) -> 0.25 | E40: In Excel output, should be as shown here | H40: Placeholder estimate
A41: =IF('Initial Screens'!$C$13="VVF","Hide","Show") -> Show | B41: Reserved Capacity Percentage | C41: =ROUND(1-C40,3) -> 0.75 | H41: Calculation
A42: =IF('Initial Screens'!$C$13="VVF","Hide","Show") -> Show | B42: RAID Overhead | C42: 1.5 | H42: FTT1/2/RAID-5/6 configuration with 3 node in a cluster
A43: =IF('Initial Screens'!$C$13="VVF","Hide","Show") -> Show | B43: Compression Ratio | C43: 1.5 | H43: Placeholder estimate
...

Sheet Network
B2: Current State Network (Host Based) Costs & Anticipated Reduction | G2: Return button
B4: Current State | H4: Sourcing & Comments
B5: Other Network Devices (primarily ToRs) as % of Host Cost | F5: 0.1 | H5: Placeholder default
B6: Number of VM Hosts | F6: =Compute!F6 -> 400 | H6: ='Initial Screens'!$E$17 -> 0
A7: =IF(Compute!$D$68="No","Hide","Show") -> Show | B7: Number of Physical legacy servers (that can be virtualized) | F7: =Compute!F73 -> 0 | H7: From Compute
B8: Average purchase cost per current state host | F8: =Compute!F8*Compute!F10+(1-Compute!F8)*Compute!F9 -> 25000 | H8: From Compute
A9: =IF(Compute!$D$68="No","Hide","Show") -> Show | B9: Average purchase cost to refresh a physical legacy server | F9: =Compute!F74 -> 5000 | H9: From Compute
B10: Annual network hardware support | F10: 0.15 | H10: Placeholder default
B11: =FIXED(AnalysisTerm,0)&"-Year Current State Cost" -> 10-Year Current State Cost | F11: =ROUND(Network!F5*Network!F6*Network!F8,0)*(1+AnalysisTerm*Network!F10) -> 2500000 | H11: Calculation
B12: Future State
B13: Other Network Devices (primarily ToRs) as % of Host Cost | F13: =ROUND(F5,3) -> 0.1 | H13: From above
A14: =IF('Initial Screens'!$C$13="VVF","Hide","Show") -> Show | B14: Number of vSAN Ready Nodes | F14: =Compute!F19+Compute!F81 -> 143 | H14: From Compute
B15: Number of ESXi Hosts | F15: =Compute!F20+Compute!F82 -> 0 | H15: From Compute
A16: =IF('Initial Screens'!$C$13="VVF","Hide","Show") -> Show | B16: Average compute cost (excludes storage component) per host (vSAN Ready Nodes) | F16: =Compute!F21 -> 25000 | H16: From Compute
B17: Average purchase cost per host (ESXi Hosts) | F17: =Compute!F22 -> 0 | H17: From Compute
B18: Annual network hardware support | F18: 0.15 | H18: Placeholder default
B19: =FIXED(AnalysisTerm,0)&"-Year Future State Cost" -> 10-Year Future State Cost | F19: =ROUND(F13*(F14*F16+F15*F17),0)*(1+AnalysisTerm*F18) -> 893750 | H19: Calculation
B21: VCF Network Add-Ons
A23: =IF('Initial Screens'!$D$26="Yes","Show","Hide") -> Hide | B23: Reduced Load Balancer Hardware
A24: =IF('Initial Screens'!$D$26="Yes","Show","Hide") -> Hide
A25: =IF('Initial Screens'!$D$26="Yes","Show","Hide") -> Hide | B25: Current State | H25: Sourcing & Comments
A26: =IF('Initial Screens'!$D$26="Yes","Show","Hide") -> Hide | B26: Number of Data Center HW Load Balancers (existing and planned) | F26: =IF('Initial Screens'!D26="Yes",C43,0) -> 0 | G26: Worksheet | H26: Assumes host traffic = 4 Gbps, LB throughput = 20 Gbps and HW LB Traffic = 25%
A27: =IF('Initial Screens'!$D$26="Yes","Show","Hide") -> Hide | B27: Cost per load balancer | F27: 87000 | H27: Based on estimated net price for F5-BIG-LTM-8900
A28: =IF('Initial Screens'!$D$26="Yes","Show","Hide") -> Hide | B28: Annual network hardware support | F28: 0.15 | H28: Placeholder default
A29: =IF('Initial Screens'!$D$26="Yes","Show","Hide") -> Hide | B29: =FIXED(AnalysisTerm,0)&"-Year Current State Cost" -> 10-Year Current State Cost | F29: =ROUND(F26*F27,0)*(1+AnalysisTerm*F28) -> 0 | H29: Calculation
A30: =IF('Initial Screens'!$D$26="Yes","Show","Hide") -> Hide | B30: Future State
A31: =IF('Initial Screens'!$D$26="Yes","Show","Hide") -> Hide | B31: ="Anticipated Percent of DC load balancers that can be retired (or purchases avoided) in "&AnalysisTerm&" years" -> Anticipated Percent of DC load balancers that can be retired (or purchases avoided) in 10 years | F31: 1 | H31: Placeholder estimate
A32: =IF('Initial Screens'!$D$26="Yes","Show","Hide") -> Hide | B32: Anticipated number of Data Center load balancers | F32: =EVEN(F26*(1-F31)) -> 0 | H32: Calculation
A33: =IF('Initial Screens'!$D$26="Yes","Show","Hide") -> Hide | B33: Annual network hardware support | F33: 0.15 | H33: Placeholder default
A34: =IF('Initial Screens'!$D$26="Yes","Show","Hide") -> Hide | B34: =FIXED(AnalysisTerm,0)&"-Year Future State Cost" -> 10-Year Future State Cost | F34: =ROUND(F32*F27,0)*(1+AnalysisTerm*F33) -> 0 | H34: Calculation
A35: =IF('Initial Screens'!$D$26="Yes","Show","Hide") -> Hide
A36: =IF('Initial Screens'!$D$26="Yes","Show","Hide") -> Hide | B36: Data Center HW Load Balancers
A37: =IF('Initial Screens'!$D$26="Yes","Show","Hide") -> Hide
A38: =IF('Initial Screens'!$D$26="Yes","Show","Hide") -> Hide | B38: Number of Hosts | C38: ='Excel Output'!$D$23 -> 400 | H38: From Inputs
A39: =IF('Initial Screens'!$D$26="Yes",IF(Compute!$D$68="No","Hide","Show"),"Hide") -> Hide | B39: Number of Physical Servers | C39: =Compute!$F$73 -> 0 | H39: From Compute
A40: =IF('Initial Screens'!$D$26="Yes","Show","Hide") -> Hide | B40: Host Traffic (Gbps) | C40: =ROUND(4,1) -> 4 | H40: Placeholder estimate
A41: =IF('Initial Screens'!$D$26="Yes","Show","Hide") -> Hide | B41: LB Throughput (Gbps) | C41: =ROUND(20,1) -> 20 | H41: Placeholder estimate
A42: =IF('Initial Screens'!$D$26="Yes","Show","Hide") -> Hide | B42: HW LB traffic | C42: =ROUND(25%,2) -> 0.25 | H42: Placeholder estimate
A43: =IF('Initial Screens'!$D$26="Yes","Show","Hide") -> Hide | B43: Number of HW Load balancers | C43: =EVEN((C38+C39)*C40/C41*C42) -> 20 | H43: Calculation
A45: =IF('Initial Screens'!$D$27="Yes","Show","Hide") -> Hide | B45: Reduced Firewall Hardware
...

Sheet Software
B2: Current VMware Annual Investment Elimination | G2: Return button
B4: Current State | H4: Sourcing & Comments | I4: =F5*((1+F6)^5-1)/F6 -> 2762815.6
A5: (i) | B5: Annual VMware Software, Subscription and Services Renewal | F5: 500000 | H5: Please update with the actual stated out year value or similar
B6: Estimated annual increase | F6: 0.05 | H6: Placeholder default
B7: =FIXED(AnalysisTerm,0)&"-Year Current State Cost" -> 10-Year Current State Cost | F7: =IF(AnalysisTerm=3,F5+F5*(1+F6)+F5*(1+F6)^2,F5+F5*(1+F6)+F5*(1+F6)^2+F5*(1+F6)^3+F5*(1+F6)^4) -> 2762815.6 | H7: Calculation
B8: Future State
B9: Anticipated reduction | F9: =ROUND(100%,3)-50% -> 0.5 | H9: Assumes elimination of cost as part of execution of new contract | J9: =F10*F6/((1+F6)^5-1) -> 250000.03
B10: =FIXED(AnalysisTerm,0)&"-Year Future State Cost" -> 10-Year Future State Cost | F10: =ROUND(F7*(1-F9),0) -> 1381408 | H10: Calculation
A12: =IF('Initial Screens'!$D$28="Yes","Show","Hide") -> Hide | B12: Software License Cost Reduction with Data Services Manager (DSM)
A13: =IF('Initial Screens'!$D$28="Yes","Show","Hide") -> Hide
A14: =IF('Initial Screens'!$D$28="Yes","Show","Hide") -> Hide | B14: Current State | H14: Sourcing & Comments
A15: =IF('Initial Screens'!$D$28="Yes","Show","Hide") -> Hide | B15: Total number of Cores | F15: =Compute!D39*Compute!D41 -> 14400 | H15: Pulled from current number of hosts times current state cores per host
A16: =IF('Initial Screens'!$D$28="Yes","Show","Hide") -> Hide | B16: Percent of Cores requiring DSM coverage | F16: =ROUND(12%,3) -> 0.12 | H16: Postgres use
A17: =IF('Initial Screens'!$D$28="Yes","Show","Hide") -> Hide | B17: Average annual cost per core for competitive offerings (management of DB) | F17: =1000 -> 1000 | H17: RDS Outpost - Annualized cost of Nutanix DB (latest pricing 2024) - Not including the DB support
A18: =IF('Initial Screens'!$D$28="Yes","Show","Hide") -> Hide | B18: =FIXED(AnalysisTerm,0)&"-Year Current State Cost" -> 10-Year Current State Cost | F18: =IF('Initial Screens'!$D$28="Yes",ROUND(F15*F16*F17*AnalysisTerm,0),0) -> 0 | H18: Calculation
A19: =IF('Initial Screens'!$D$28="Yes","Show","Hide") -> Hide | B19: Future State
A20: =IF('Initial Screens'!$D$28="Yes","Show","Hide") -> Hide | B20: Anticipated reduction | F20: 1 | H20: Assumes full takeout
A21: =IF('Initial Screens'!$D$28="Yes","Show","Hide") -> Hide | B21: =FIXED(AnalysisTerm,0)&"-Year Future State Cost" -> 10-Year Future State Cost | F21: =IF('Initial Screens'!$D$28="Yes",ROUND(F18*(1-F20),0),0) -> 0 | H21: Calculation
B23: Include Custom Benefit | C23: No
B25: Other Reduced Software Cost(s)
B27: Current State | H27: Sourcing & Comments
B28: Number of software subscription contracts
B29: Annual average cost per contract
B30: =FIXED(AnalysisTerm,0)&"-Year Current State Cost" -> 10-Year Current State Cost | F30: =IFERROR(ROUND(F28*F29*AnalysisTerm,0),"") -> 0 | H30: Calculation
B31: Future State
B32: Percent to be impacted by VMware | F32: 1
B33: Anticipated cost reduction
B34: =FIXED(AnalysisTerm,0)&"-Year Future State Cost" -> 10-Year Future State Cost | F34: =IFERROR(ROUND((F30*(1-F32)+F30*F32*(1-F33))*AnalysisTerm,0),"") -> 0 | H34: Calculation

Sheet Facilities
B2: Reduced Power, Cooling, Rack Costs | G2: Return button
B4: Current State | H4: Sourcing & Comments
B5: Number of VM Hosts | F5: ='Excel Output'!$D$23+Compute!$F$94*'Excel Output'!$D$23 -> 400 | H5: =Compute!H6 -> 0
B6: Opex per host per year (rack, power, cooling) | F6: =F57 -> 6032 | G6: Worksheet | H6: From worksheet
A7: =IF(Compute!$D$68="No","Hide","Show") -> Show | B7: Number of Physical legacy servers | F7: =Compute!F73 -> 0 | H7: =Compute!H73 -> 0
A8: =IF(Compute!$D$68="No","Hide","Show") -> Show | B8: Opex per physical legacy server per year (rack, power, cooling) | F8: =F58 -> 5151 | H8: From worksheet
A9: =IF('Initial Screens'!$D$26="Yes","Show","Hide") -> Hide | B9: Number of load balancers | F9: =IF('Initial Screens'!$D$26="Yes",Network!F26,0) -> 0 | H9: From Network Calculation Section Above (Reduced Load Balancer Hardware)
A10: =IF('Initial Screens'!$D$26="Yes","Show","Hide") -> Hide | B10: Opex per load balancer per year (rack, power, cooling) | F10: =IF('Initial Screens'!$D$26="Yes",F59,0) -> 0 | G10: Worksheet | H10: From worksheet
A11: =IF('Initial Screens'!$D$27="Yes","Show","Hide") -> Hide | B11: Number of firewalls | F11: =IF('Initial Screens'!$D$27="Yes",Network!F48,0) -> 0 | H11: From Network Calculation Section Above (Reduced Firewall Hardware)
A12: =IF('Initial Screens'!$D$27="Yes","Show","Hide") -> Hide | B12: Opex per firewalls per year (rack, power, cooling) | F12: =IF('Initial Screens'!$D$27="Yes",F60,0) -> 0 | G12: Worksheet | H12: From worksheet
B13: =FIXED(AnalysisTerm,0)&"-Year Current State Cost" -> 10-Year Current State Cost | F13: =ROUND(F5*F6+F7*F8+F9*F10+F11*F12,0)*AnalysisTerm -> 24128000 | H13: Calculation
B14: Future State
B15: Number of Hosts (vSAN Ready Nodes & ESXi Hosts) | F15: =Compute!F17+Compute!F81+Compute!F82 -> 143 | H15: From Compute
B16: Opex per vSAN Ready Node per year (rack, power, cooling) | F16: =ROUND($F$6*IF(AND(Compute!F41>Compute!D41,Compute!F42>Compute!D42),0.9,1),0) -> 5429 | H16: From above
A17: =IF('Initial Screens'!$D$26="Yes","Show","Hide") -> Hide | B17: Number of load balancers | F17: =IF('Initial Screens'!$D$26="Yes",Network!F32,0) -> 0 | H17: From Network sheet
A18: =IF('Initial Screens'!$D$26="Yes","Show","Hide") -> Hide | B18: Opex per load balancer per year (rack, power, cooling) | F18: =F10 -> 0 | H18: From above
A19: =IF('Initial Screens'!$D$27="Yes","Show","Hide") -> Hide | B19: Number of firewalls | F19: =IF('Initial Screens'!$D$27="Yes",Network!F54,0) -> 0 | H19: From Network sheet
A20: =IF('Initial Screens'!$D$27="Yes","Show","Hide") -> Hide | B20: Opex per firewalls per year (rack, power, cooling) | F20: =F12 -> 0 | H20: From above
B21: =FIXED(AnalysisTerm,0)&"-Year Future State Cost" -> 10-Year Future State Cost | F21: =ROUND(F15*F16+F17*F18+F19*F20,0)*AnalysisTerm -> 7763470 | H21: Calculation
B23: Current State Ongoing Opex per device per year
B24: Power & Cooling Requirement | H24: Sourcing & Comments
B25: 24 x 7 Operations for DC HW (365*24) | F25: =ROUND(365*24,0) -> 8760 | H25: Assumes 365 days x 24 hours per year
B26: Operational Power rating per Physical Host (kW) | F26: =ROUND(0.65,2) -> 0.65 | H26: Placeholder estimate
A27: =IF(Compute!$D$68="No","Hide","Show") -> Show | B27: Operational Power rating per physical legacy server (kW) | F27: =ROUND(0.3,2) -> 0.3 | H27: Placeholder estimate
A28: =IF('Initial Screens'!$D$26="Yes","Show","Hide") -> Hide | B28: Operational Power rating per Load balancer (kW) | F28: =ROUND(0.3,2) -> 0.3 | H28: Placeholder estimate
A29: =IF('Initial Screens'!$D$27="Yes","Show","Hide") -> Hide | B29: Operational Power rating per Firewall (kW) | F29: =ROUND(0.3,2) -> 0.3 | H29: Placeholder estimate
B30: Burdened rate for additional Network and Storage Devices | F30: =ROUND(30%,2) -> 0.3 | H30: Placeholder estimate
B31: Power Usage Effectiveness- On-Premise DC | F31: =ROUND(1.7,1) -> 1.7 | H31: Placeholder estimate
B32: Resultant annual power consumption per physical host (KWh) | F32: =ROUND($F$25*F26*(1+$F$30)*$F$31,0) -> 12584 | H32: Calculation
A33: =IF(Compute!$D$68="No","Hide","Show") -> Show | B33: Resultant annual power consumption per physical legacy server (KWh) | F33: =ROUND($F$25*F27*(1+$F$30)*$F$31,0) -> 5808 | H33: Calculation
A34: =IF('Initial Screens'!$D$26="Yes","Show","Hide") -> Hide | B34: Resultant annual power consumption per load balancer (KWh) | F34: =ROUND($F$25*F28*(1+$F$30)*$F$31,0) -> 5808 | H34: Calculation
A35: =IF('Initial Screens'!$D$27="Yes","Show","Hide") -> Hide | B35: Resultant annual power consumption per firewall (KWh) | F35: =ROUND($F$25*F29*(1+$F$30)*$F$31,0) -> 5808 | H35: Calculation
B36: Electricity cost per kWh | F36: 0.13 | H36: https://www.globalpetrolprices.com/electricity_prices/#hl48
B37: Annual Power & Cooling Cost Per device
B38: VM Host | F38: =ROUND(F32*$F$36,0) -> 1636 | H38: Calculation
A39: =IF(Compute!$D$68="No","Hide","Show") -> Show | B39: Physical legacy server | F39: =ROUND(F33*$F$36,0) -> 755 | H39: Calculation
A40: =IF('Initial Screens'!$D$26="Yes","Show","Hide") -> Hide | B40: Load balancer | F40: =ROUND(F34*$F$36,0) -> 755 | H40: Calculation
A41: =IF('Initial Screens'!$D$27="Yes","Show","Hide") -> Hide | B41: Firewall | F41: =ROUND(F35*$F$36,0) -> 755 | H41: Calculation
B42: Data Center Space Requirement
B43: Unit for data center space/area calculations | F43: Sq. Feet | H43: Based on Region
...

Sheet Labor
K1: =(F60*F107*F108)/2080 -> 0
B2: Labor Productivity | G2: Return button
B4: Total Number of FTE(s) involved cosidered in Current state | F4: =ROUND(Misc!C156,1) -> 25.2 | H4: Calculation -Sum of all the individual FTEs cosnidered for estimating the operational efficiency improvement
B5: Total recaptured labor hours in future state | F5: =(F4*2080)*(1-F6) -> 27828.874 | H5: Calculation -Sum of all the individual FTEs cosnidered for estimating the operational efficiency improvement
B6: Anticipated Efficiency improvement | F6: =(F127-F128)/F127 -> 0.46907674 | H6: Calculation- Sum of all the individual FTEs cosnidered for estimating the operational efficiency improvement
B8: Server Admin Productivity
B9: Current State | H9: Sourcing & Comments
B10: Number of Server Administrators | F10: =ROUND(MIN(10,'Excel Output'!$D$22/1000),1) -> 5 | H10: Assumes 1000 VMs per admin
B11: Average annual fully burdened cost per server admin FTE | F11: =ROUND(Benchmarks!$D$16,2) -> 175032.71 | H11: ="Skillsoft 2024 IT Skills and Salary Report Benchmark for "&'Initial Screens'!$C$9&" "&'Initial Screens'!$C$8&" + conservative "&FIXED(Benchmarks!$D$45*100,1)&"% burden rate per" -> Skillsoft 2024 IT Skills and Salary Report Benchmark for AMER Financial Services + conservative 45.0% burden rate per
B12: Current State Annualized Cost | F12: =ROUND(F10*F11,0) -> 875164 | H12: Calculation
B13: Future State
B14: Anticipated percent productivity gain | F14: =IF(ISNUMBER(SEARCH("VCF",'Initial Screens'!$C$13)),MIN(50%,ROUND(40%*(1+Compute!$D$29),3)),ROUND(20%,3)) -> 0.48 | H14: Placeholder estimate
B15: Future State Annualized Cost | F15: =ROUND(F12*(1-F14),0) -> 455085 | H15: Calculation
A17: =IF('Initial Screens'!$C$13="VVF","Hide","Show") -> Show | B17: Storage Admin Productivity
A18: =IF('Initial Screens'!$C$13="VVF","Hide","Show") -> Show | B18: Current State | H18: Sourcing & Comments
A19: =IF('Initial Screens'!$C$13="VVF","Hide","Show") -> Show | B19: Number of storage administrator personnel | F19: =IF(A17="Show",ROUND(MIN(10,'Excel Output'!D22*'Excel Output'!D24/1000/300),1),0) -> 5 | H19: Assumes 300 TBs per admin
A20: =IF('Initial Screens'!$C$13="VVF","Hide","Show") -> Show | B20: Average annual fully burdened cost per storage administrator FTE | F20: =ROUND(Benchmarks!$D$16,2) -> 175032.71 | H20: ="Skillsoft 2024 IT Skills and Salary Report Benchmark for "&'Initial Screens'!$C$9&" "&'Initial Screens'!$C$8&" + conservative "&FIXED(Benchmarks!$D$45*100,1)&"% burden rate per" -> Skillsoft 2024 IT Skills and Salary Report Benchmark for AMER Financial Services + conservative 45.0% burden rate per
A21: =IF('Initial Screens'!$C$13="VVF","Hide","Show") -> Show | B21: Current State Annualized Cost | F21: =ROUND(F19*F20,0) -> 875164 | H21: Calculation
A22: =IF('Initial Screens'!$C$13="VVF","Hide","Show") -> Show | B22: Future State
A23: =IF('Initial Screens'!$C$13="VVF","Hide","Show") -> Show | B23: Anticipated percent productivity gain | F23: =MIN(50%,ROUND(40%*Misc!$E$139*(1+(Storage!F11-Storage!F25)/Storage!F11),3)) -> 0.5 | H23: Placeholder estimate
A24: =IF('Initial Screens'!$C$13="VVF","Hide","Show") -> Show | B24: Future State Annualized Cost | F24: =ROUND(F21*(1-F23),0) -> 437582 | H24: Calculation
A26: =IF(ISNUMBER(SEARCH("VCF",'Initial Screens'!$C$13)),"Show",IF(OR('Initial Screens'!$D$26="Yes",'Initial Screens'!$D$27="Yes"),"Show","Hide")) -> Show | B26: Network Admin (provisioning/troubleshooting) Productivity
A27: =$A$26 -> Show | B27: Current State | H27: Sourcing & Comments
A28: =$A$26 -> Show | B28: Number of network administrator personnel | F28: =ROUND(MIN(10,'Excel Output'!$D$22/1000),1) -> 5 | H28: Assumes 1000 VMs per admin
A29: =$A$26 -> Show | B29: Average annual fully burdened cost per network administrator FTE | F29: =ROUND(Benchmarks!$D$16,2) -> 175032.71 | H29: ="Skillsoft 2024 IT Skills and Salary Report Benchmark for "&'Initial Screens'!$C$9&" "&'Initial Screens'!$C$8&" + conservative "&FIXED(Benchmarks!$D$45*100,1)&"% burden rate per" -> Skillsoft 2024 IT Skills and Salary Report Benchmark for AMER Financial Services + conservative 45.0% burden rate per
A30: =$A$26 -> Show | B30: Current State Annualized Cost | F30: =ROUND(F28*F29,0) -> 875164 | H30: Calculation
A31: =$A$26 -> Show | B31: Future State
A32: =$A$26 -> Show | B32: Anticipated productivity gain | F32: =IF(ISNUMBER(SEARCH("VCF",'Initial Screens'!$C$13)),MIN(50%,ROUND(40%*(1+Compute!$D$29)*('Excel Output'!E29-'Excel Output'!D29),3)),ROUND(20%,3)) -> 0.48 | H32: Placeholder estimate
A33: =$A$26 -> Show | B33: Future State Annualized Cost | F33: =ROUND(F30*(1-F32),0) -> 455085 | H33: Calculation
A35: =IF(ISNUMBER(SEARCH("VCF",'Initial Screens'!$C$13)),"Show","Hide") -> Show | B35: Service Delivery (IaaS/Private Cloud) Productivity | K35: =3000*2.5 -> 7500
A36: =$A$35 -> Show | B36: Current State | H36: Sourcing & Comments | K36: =K35/1960 -> 3.8265306
A37: =$A$35 -> Show | B37: Number of IT service delivery personnel required for provisioning and deploying new VMS | F37: =IF(A35="Show",ROUND(MIN(10,'Excel Output'!$D$22/1000),1),0) -> 5 | H37: Assumes 1000 VMs per admin
A38: =$A$35 -> Show | B38: Average annual fully burdened cost per IT service delivery FTE | F38: =ROUND(Benchmarks!$D$16,2) -> 175032.71 | H38: ="Skillsoft 2024 IT Skills and Salary Report Benchmark for "&'Initial Screens'!$C$9&" "&'Initial Screens'!$C$8&" + conservative "&FIXED(Benchmarks!$D$45*100,1)&"% burden rate per" -> Skillsoft 2024 IT Skills and Salary Report Benchmark for AMER Financial Services + conservative 45.0% burden rate per | K38: =3000/K36 -> 784
A39: =$A$35 -> Show | B39: Current State Annualized Cost | F39: =ROUND(F37*F38,0) -> 875164 | H39: Calculation
A40: =$A$35 -> Show | B40: Future State
A41: =$A$35 -> Show | B41: Anticipated percent reduction in deploying new VMs | F41: =IF(ISNUMBER(SEARCH("VCF",'Initial Screens'!$C$13)),MIN(50%,ROUND(40%*(1+Compute!$D$29)*Misc!E137,3)),ROUND(20%,3)) -> 0.48 | H41: Placeholder estimate based on The Total Economic Impact™ Of VMware Cloud Foundation Automations
A42: =$A$35 -> Show | B42: Future State Annualized Cost | F42: =ROUND(F39*(1-F41),0) -> 455085 | H42: Calculation
A44: =IF(ISNUMBER(SEARCH("VCF",'Initial Screens'!$C$13)),"Show","Hide") -> Show | B44: =IF('Initial Screens'!C13="VCF 9", "Operational Efficency for Enterprise/Cloud Admin with VCF operations","Software Defined Datacenter (SDDC) Manager Productivity") -> Operational Efficency for Enterprise/Cloud Admin with VCF operations
A45: =$A$44 -> Show | B45: Current State | H45: Sourcing & Comments
A46: =$A$44 -> Show | B46: =IF('Initial Screens'!C13="VCF 9","Number of Cloud/Enterprise Admin", "Number of IT admin for existing SDDC Software LCM") -> Number of Cloud/Enterprise Admin | F46: =IF(A44="Show",ROUND(3,1),0) -> 3 | H46: Placeholder estimate
...

Sheet Support
B2: Current VMware Support Investment Elimination | G2: Return button | H2: any values in yellow input cells for illustration only
B4: Current State | H4: Sourcing & Comments
B5: Annual VMware Support (e.g., TAM, etc.) | F5: 250000
B6: Estimated annual increase | F6: 0
B7: =FIXED(AnalysisTerm,0)&"-Year Current State Cost" -> 10-Year Current State Cost | F7: =IF(AnalysisTerm=3,F5+F5*(1+F6)+F5*(1+F6)^2,F5+F5*(1+F6)+F5*(1+F6)^2+F5*(1+F6)^3+F5*(1+F6)^4) -> 1250000 | H7: Calculation
B8: Future State
B9: Anticipated reduction | F9: 0.5 | H9: Assumes elimination of cost as part of execution of new contract (that may or may not include new support)
B10: =FIXED(AnalysisTerm,0)&"-Year Future State Cost" -> 10-Year Future State Cost | F10: =ROUND(F7*(1-F9),0) -> 625000 | H10: Calculation

Sheet Migration - Reskilling
B2: Include Migration Efficiency? | C2: Yes
A4: =IF($C$2="Yes","Show","Hide") -> Show | B4: =IF('Initial Screens'!C13="VCF 9","Migration Efficiency (related to host refresh and migration to VCF 9)","Migration Efficiency (related to host refresh)") -> Migration Efficiency (related to host refresh and migration to VCF 9) | G4: Return button
A5: =IF($C$2="Yes","Show","Hide") -> Show
A6: =IF($C$2="Yes","Show","Hide") -> Show | B6: Current State | H6: Sourcing & Comments
A7: =IF($C$2="Yes","Show","Hide") -> Show | B7: Number of VMs | F7: =IF(C2="Yes",'Excel Output'!D22,0) -> 5000 | H7: ='Initial Screens'!$E$16 -> 0
A8: =IF($C$2="Yes","Show","Hide") -> Show | B8: Expected percent of VMs to migrate over duration of analysis | F8: =ROUND(100%,3) -> 1 | H8: Assumes full migration
A9: =IF($C$2="Yes","Show","Hide") -> Show | B9: Average hours to migrate a VM (to the cloud or during a HW refresh) | F9: =ROUND(1,1) -> 1 | H9: VMware Benchmark (assumes vSphere only current state)
A10: =IF($C$2="Yes","Show","Hide") -> Show | B10: Fully burdened IT labor cost per hour | F10: =ROUND(Benchmarks!$D$10,2) -> 97.5 | H10: ="Skillsoft 2024 IT Skills and Salary Report Benchmark for "&'Initial Screens'!$C$9&" "&'Initial Screens'!$C$8&" + conservative "&FIXED(Benchmarks!$D$45*100,1)&"% burden rate per" -> Skillsoft 2024 IT Skills and Salary Report Benchmark for AMER Financial Services + conservative 45.0% burden rate per
A11: =IF($C$2="Yes","Show","Hide") -> Show | B11: =FIXED(AnalysisTerm,0)&"-Year Current State Cost" -> 10-Year Current State Cost | F11: =ROUND(F7*F8*F9*F10*AnalysisTerm,0) -> 4875000 | H11: Calculation
A12: =IF($C$2="Yes","Show","Hide") -> Show | B12: Future State
A13: =IF($C$2="Yes","Show","Hide") -> Show | B13: Anticipated percent reduction | F13: =ROUND(75%,3) -> 0.75 | H13: VMware Benchmark (assumes VCF w/ HCX)
A14: =IF($C$2="Yes","Show","Hide") -> Show | B14: =FIXED(AnalysisTerm,0)&"-Year Future State Cost" -> 10-Year Future State Cost | F14: =ROUND(F11*(1-F13),0) -> 1218750 | H14: Calculation
B16: Reskilling | G16: Return button
B18: Current State
B19: Number of FTEs (Server, Storage, Network, Service Delivery) | F19: =Labor!F10+Labor!F28+Labor!F19+Labor!F37 -> 20 | H19: From labor
B20: Annual Training Hours per year | F20: =ROUND(20,1) -> 20 | H20: Placeholder estimate
B21: Total Training Hours per year | F21: =F19*F20 -> 400 | H21: Calculation
B22: Fully burdened IT labor cost per hour | F22: =ROUND(Benchmarks!$D$10,2) -> 97.5 | H22: ="Skillsoft 2024 IT Skills and Salary Report Benchmark for "&'Initial Screens'!$C$9&" "&'Initial Screens'!$C$8&" + conservative "&FIXED(Benchmarks!$D$45*100,1)&"% burden rate per" -> Skillsoft 2024 IT Skills and Salary Report Benchmark for AMER Financial Services + conservative 45.0% burden rate per
B23: One Time Current State Reskilling cost | F23: =F21*F22 -> 39000 | H23: Calculation
B24: Future State
B25: Number of FTEs (Server, Storage, Network, Service Delivery) | F25: =Labor!F10+Labor!F28+Labor!F19+Labor!F37 -> 20 | H25: From labor
B26: Average Training Hours for Reskilling (one time) | F26: =ROUND(20*(('Excel Output'!E27-'Excel Output'!D27)+('Excel Output'!E28-'Excel Output'!D28)+('Excel Output'!E29-'Excel Output'!D29)+('Excel Output'!E30-'Excel Output'!D30)),1) -> 80 | H26: Calculation based on current-future state coverage for Ops, Automation, vSAN, and NSX
B27: Total Training Hours for reskilling | F27: =F25*F26 -> 1600 | H27: Calculation
B28: Fully burdened IT labor cost per hour | F28: =ROUND(Benchmarks!$D$10,2) -> 97.5 | H28: ="Skillsoft 2024 IT Skills and Salary Report Benchmark for "&'Initial Screens'!$C$9&" "&'Initial Screens'!$C$8&" + conservative "&FIXED(Benchmarks!$D$45*100,1)&"% burden rate per" -> Skillsoft 2024 IT Skills and Salary Report Benchmark for AMER Financial Services + conservative 45.0% burden rate per
B29: One Time Future State Reskilling cost | F29: =F27*F28 -> 156000 | H29: Calculation

Sheet InvestmentBVA
F6: =IF(#REF!<=3,"hide column","show column") -> #REF! | G6: =IF(#REF!<=4,"hide column","show column") -> #REF!
B7: Multi-year Impact (likely)
B9: Estimated Investment | C9: Year 1 | D9: Year 2 | E9: Year 3 | F9: =IF(#REF!>3,"Year 4","") -> #REF! | G9: =IF(#REF!>4,"Year 5","") -> #REF! | H9: Total
B10: Subscription | H10: =SUM(C10:G10) -> 0
B11: License | H11: =SUM(C11:G11) -> 0
B12: Maintenance (SnS) | H12: =SUM(C12:G12) -> 0
B13: Professional Services | H13: =SUM(C13:G13) -> 0
B14: Education / Training | H14: =SUM(C14:G14) -> 0
B15: Success360 / TAM | H15: =SUM(C15:G15) -> 0
B16: Other | H16: =SUM(C16:G16) -> 0
B17: Organizational Change Management (Consulting) | H17: =SUM(C17:G17) -> 0
B18: Organizational Change Management (Internal) | H18: =SUM(C18:G18) -> 0
B19: User Defined | H19: =SUM(C19:G19) -> 0
B20: Total Investment | C20: =SUM(C10:C19) -> 0 | D20: =SUM(D10:D19) -> 0 | E20: =SUM(E10:E19) -> 0 | F20: =SUM(F10:F19) -> 0 | G20: =SUM(G10:G19) -> 0 | H20: =SUM(H10:H19) -> 0
B21: Note: All pricing herein is an estimation and not an approved quote or formal proposal.

Sheet Misc
B2: Accordion Totals
C4: Current State | D4: Future State | E4: Future State for TCO Model (VCF at List Price)
B5: Compute | C5: =Compute!F12+Compute!F76+Compute!F100 -> 25000000 | D5: =Compute!F24+Compute!F86+Compute!F112 -> 8937500 | E5: =Transition!D11 -> 8937500
B6: Storage | C6: =Storage!F21+Compute!F101 -> 11964285 | D6: =Storage!F34+Compute!F113 -> 2940000 | E6: =Transition!D12 -> 2940000
B7: Network | C7: =Network!F11+Network!F29+Network!F51+Compute!F102 -> 2500000 | D7: =Network!F19+Network!F34+Network!F56+Compute!F114 -> 893750 | E7: =Transition!D13 -> 893750
B8: Software | C8: =Software!F7+Software!F18+Software!F30 -> 2762815.6 | D8: =Software!F10+Software!F21+Software!F34+'ROI Results'!O37 -> 8881408 | E8: =Transition!D14 -> 10000000
B9: Facilities | C9: =Facilities!F13 -> 24128000 | D9: =Facilities!F21 -> 7763470 | E9: =Transition!D15 -> 7763470
B10: Labor | C10: =Labor!F127 -> 44760535 | D10: =Labor!F128 -> 23764409 | E10: =Transition!D16 -> 23764409
B11: Support | C11: =Support!F7 -> 1250000 | D11: =Support!F10+'ROI Results'!O40 -> 1375000 | E11: =Transition!D17 -> 750000
B12: Migration | C12: ='Migration - Reskilling'!F11 -> 4875000 | D12: ='Migration - Reskilling'!F14 -> 1218750 | E12: =Transition!D18 -> 1218750
B13: One-time Reskilling | C13: ='Migration - Reskilling'!F23 -> 39000 | D13: ='Migration - Reskilling'!F29 -> 156000 | E13: =Transition!D19 -> 156000
B14: Sum of Annualized Business Benefits | C14: ='Business impact'!F19+'Business impact'!F34+'Business impact'!F54+'Business impact'!F65+'Business impact'!F77 -> 0
B16: CapEx v OpEx Calcs
E17: CapEx
B18: ='ROI Results'!$B$70 -> Ongoing current state (TCO) | E18: Year 1 | F18: Year 2 | G18: Year 3 | H18: =IF(AnalysisTerm>3,4,"") -> 4 | I18: =IF(AnalysisTerm>3,H18+1,"") -> 5 | J18: =IF(AnalysisTerm>5,I18+1,"") -> 6 | K18: =IF(AnalysisTerm>5,J18+1,"") -> 7 | L18: =IF(AnalysisTerm>7,K18+1,"") -> 8 | M18: =IF(AnalysisTerm>7,L18+1,"") -> 9 | N18: =IF(AnalysisTerm>7,M18+1,"") -> 10 | O18: Total
B19: Compute | E19: =(Hardware_Refreshcylce+Growth)*'ROI Results'!$C71 -> 2618750 | F19: =((Hardware_Refreshcylce+(1+Growth)^2-(1+Growth))*'ROI Results'!$C71)*(1+Inflation)^1 -> 2724285.6 | G19: =((Hardware_Refreshcylce+(1+Growth)^3-(1+Growth)^2)*'ROI Results'!$C71)*(1+Inflation)^2 -> 2835185.6 | H19: =IF(AnalysisTerm>3,((Hardware_Refreshcylce+(1+Growth)^H$18-(1+Growth)^3)*'ROI Results'!$C71)*(1+Inflation)^3,"") -> 2951790.1 | I19: =IF(AnalysisTerm>3,((Hardware_Refreshcylce+(1+Growth)^I$18-(1+Growth)^H$18)*'ROI Results'!$C71)*(1+Inflation)^H$18," ") -> 3074463.9 | J19: =IF(AnalysisTerm>$I$18,((Hardware_Refreshcylce+(1+Growth)^J$18-(1+Growth)^I$18)*'ROI Results'!$C71)*(1+Inflation)^I$18," ") -> 3203598.8 | K19: =IF(AnalysisTerm>$I$18,((Hardware_Refreshcylce+(1+Growth)^K$18-(1+Growth)^J$18)*'ROI Results'!$C71)*(1+Inflation)^J$18," ") -> 3339615.1 | L19: =IF(AnalysisTerm>$K$18,((Hardware_Refreshcylce+(1+Growth)^L$18-(1+Growth)^K$18)*'ROI Results'!$C71)*(1+Inflation)^K$18," ") -> 3482964.5 | M19: =IF(AnalysisTerm>$K$18,((Hardware_Refreshcylce+(1+Growth)^M$18-(1+Growth)^L$18)*'ROI Results'!$C71)*(1+Inflation)^L$18," ") -> 3634131.9 | N19: =IF(AnalysisTerm>$K$18,((Hardware_Refreshcylce+(1+Growth)^N$18-(1+Growth)^M$18)*'ROI Results'!$C71)*(1+Inflation)^M$18," ") -> 3793638.7 | O19: =SUM(E19:N19) -> 31658424 | P19: =SUM(E19+E32)='ROI Results'!E71 -> TRUE | Q19: =SUM(F19+F32)='ROI Results'!F71 -> TRUE | R19: =SUM(G19+G32)='ROI Results'!G71 -> TRUE | S19: =SUM(H19+H32)='ROI Results'!H71 -> TRUE | T19: =SUM(I19+I32)='ROI Results'!I71 -> TRUE | U19: =SUM(J19+J32)='ROI Results'!J71 -> TRUE | V19: =SUM(K19+K32)='ROI Results'!K71 -> TRUE | W19: =SUM(L19+L32)='ROI Results'!L71 -> TRUE | ... Z19: =SUM(O19+O32)='ROI Results'!O71 -> TRUE
B20: Storage | E20: =(Hardware_Refreshcylce+Growth)*'ROI Results'!$C72 -> 1196428.5 | F20: =((Hardware_Refreshcylce+(1+Growth)^2-(1+Growth))*'ROI Results'!$C72)*(1+Inflation)^1 -> 1244644.6 | G20: =((Hardware_Refreshcylce+(1+Growth)^3-(1+Growth)^2)*'ROI Results'!$C72)*(1+Inflation)^2 -> 1295311.5 | H20: =IF(AnalysisTerm>3,((Hardware_Refreshcylce+(1+Growth)^H$18-(1+Growth)^3)*'ROI Results'!$C72)*(1+Inflation)^3,"") -> 1348584.6 | I20: =IF(AnalysisTerm>3,((Hardware_Refreshcylce+(1+Growth)^I$18-(1+Growth)^H$18)*'ROI Results'!$C72)*(1+Inflation)^H$18," ") -> 1404630.6 | J20: =IF(AnalysisTerm>$I$18,((Hardware_Refreshcylce+(1+Growth)^J$18-(1+Growth)^I$18)*'ROI Results'!$C72)*(1+Inflation)^I$18," ") -> 1463628.4 | K20: =IF(AnalysisTerm>$I$18,((Hardware_Refreshcylce+(1+Growth)^K$18-(1+Growth)^J$18)*'ROI Results'!$C72)*(1+Inflation)^J$18," ") -> 1525770.2 | L20: =IF(AnalysisTerm>$K$18,((Hardware_Refreshcylce+(1+Growth)^L$18-(1+Growth)^K$18)*'ROI Results'!$C72)*(1+Inflation)^K$18," ") -> 1591262.2 | M20: =IF(AnalysisTerm>$K$18,((Hardware_Refreshcylce+(1+Growth)^M$18-(1+Growth)^L$18)*'ROI Results'!$C72)*(1+Inflation)^L$18," ") -> 1660326.1 | N20: =IF(AnalysisTerm>$K$18,((Hardware_Refreshcylce+(1+Growth)^N$18-(1+Growth)^M$18)*'ROI Results'!$C72)*(1+Inflation)^M$18," ") -> 1733200 | O20: =SUM(E20:N20) -> 14463787 | P20: =SUM(E20+E33)='ROI Results'!E72 -> TRUE | Q20: =SUM(F20+F33)='ROI Results'!F72 -> TRUE | R20: =SUM(G20+G33)='ROI Results'!G72 -> TRUE | S20: =SUM(H20+H33)='ROI Results'!H72 -> TRUE | T20: =SUM(I20+I33)='ROI Results'!I72 -> TRUE | U20: =SUM(J20+J33)='ROI Results'!J72 -> TRUE | V20: =SUM(K20+K33)='ROI Results'!K72 -> TRUE | W20: =SUM(L20+L33)='ROI Results'!L72 -> TRUE | ... Z20: =SUM(O20+O33)='ROI Results'!O72 -> TRUE
B21: Network | E21: =(Hardware_Refreshcylce+Growth)*'ROI Results'!$C73 -> 261875 | F21: =((Hardware_Refreshcylce+(1+Growth)^2-(1+Growth))*'ROI Results'!$C73)*(1+Inflation)^1 -> 272428.56 | G21: =((Hardware_Refreshcylce+(1+Growth)^3-(1+Growth)^2)*'ROI Results'!$C73)*(1+Inflation)^2 -> 283518.56 | H21: =IF(AnalysisTerm>3,((Hardware_Refreshcylce+(1+Growth)^H$18-(1+Growth)^3)*'ROI Results'!$C73)*(1+Inflation)^3,"") -> 295179.01 | I21: =IF(AnalysisTerm>3,((Hardware_Refreshcylce+(1+Growth)^I$18-(1+Growth)^H$18)*'ROI Results'!$C73)*(1+Inflation)^H$18," ") -> 307446.39 | J21: =IF(AnalysisTerm>$I$18,((Hardware_Refreshcylce+(1+Growth)^J$18-(1+Growth)^I$18)*'ROI Results'!$C73)*(1+Inflation)^I$18," ") -> 320359.88 | K21: =IF(AnalysisTerm>$I$18,((Hardware_Refreshcylce+(1+Growth)^K$18-(1+Growth)^J$18)*'ROI Results'!$C73)*(1+Inflation)^J$18," ") -> 333961.51 | L21: =IF(AnalysisTerm>$K$18,((Hardware_Refreshcylce+(1+Growth)^L$18-(1+Growth)^K$18)*'ROI Results'!$C73)*(1+Inflation)^K$18," ") -> 348296.45 | M21: =IF(AnalysisTerm>$K$18,((Hardware_Refreshcylce+(1+Growth)^M$18-(1+Growth)^L$18)*'ROI Results'!$C73)*(1+Inflation)^L$18," ") -> 363413.19 | N21: =IF(AnalysisTerm>$K$18,((Hardware_Refreshcylce+(1+Growth)^N$18-(1+Growth)^M$18)*'ROI Results'!$C73)*(1+Inflation)^M$18," ") -> 379363.87 | O21: =SUM(E21:N21) -> 3165842.4 | P21: =SUM(E21+E34)='ROI Results'!E73 -> TRUE | Q21: =SUM(F21+F34)='ROI Results'!F73 -> TRUE | R21: =SUM(G21+G34)='ROI Results'!G73 -> TRUE | S21: =SUM(H21+H34)='ROI Results'!H73 -> TRUE | T21: =SUM(I21+I34)='ROI Results'!I73 -> TRUE | U21: =SUM(J21+J34)='ROI Results'!J73 -> FALSE | V21: =SUM(K21+K34)='ROI Results'!K73 -> TRUE | W21: =SUM(L21+L34)='ROI Results'!L73 -> TRUE | ... Z21: =SUM(O21+O34)='ROI Results'!O73 -> TRUE
B22: Software | E22: 0 | F22: 0 | G22: 0 | H22: 0 | I22: 0 | J22: 0 | K22: 0 | L22: 0 | M22: 0 | N22: 0 | O22: =SUM(E22:N22) -> 0 | P22: =SUM(E22+E35)='ROI Results'!E74 -> TRUE | Q22: =SUM(F22+F35)='ROI Results'!F74 -> TRUE | R22: =SUM(G22+G35)='ROI Results'!G74 -> TRUE | S22: =SUM(H22+H35)='ROI Results'!H74 -> TRUE | T22: =SUM(I22+I35)='ROI Results'!I74 -> TRUE | U22: =SUM(J22+J35)='ROI Results'!J74 -> TRUE | V22: =SUM(K22+K35)='ROI Results'!K74 -> TRUE | W22: =SUM(L22+L35)='ROI Results'!L74 -> TRUE | ... Z22: =SUM(O22+O35)='ROI Results'!O74 -> TRUE
B23: Facilities | E23: 0 | F23: 0 | G23: 0 | H23: 0 | I23: 0 | J23: 0 | K23: 0 | L23: 0 | M23: 0 | N23: 0 | O23: =SUM(E23:N23) -> 0 | P23: =SUM(E23+E36)='ROI Results'!E75 -> TRUE | Q23: =SUM(F23+F36)='ROI Results'!F75 -> TRUE | R23: =SUM(G23+G36)='ROI Results'!G75 -> TRUE | S23: =SUM(H23+H36)='ROI Results'!H75 -> TRUE | T23: =SUM(I23+I36)='ROI Results'!I75 -> TRUE | U23: =SUM(J23+J36)='ROI Results'!J75 -> TRUE | V23: =SUM(K23+K36)='ROI Results'!K75 -> TRUE | W23: =SUM(L23+L36)='ROI Results'!L75 -> TRUE | ... Z23: =SUM(O23+O36)='ROI Results'!O75 -> TRUE
B24: Labor | E24: 0 | F24: 0 | G24: 0 | H24: 0 | I24: 0 | J24: 0 | K24: 0 | L24: 0 | M24: 0 | N24: 0 | O24: =SUM(E24:N24) -> 0 | P24: =SUM(E24+E37)='ROI Results'!E76 -> TRUE | Q24: =SUM(F24+F37)='ROI Results'!F76 -> TRUE | R24: =SUM(G24+G37)='ROI Results'!G76 -> TRUE | S24: =SUM(H24+H37)='ROI Results'!H76 -> TRUE | T24: =SUM(I24+I37)='ROI Results'!I76 -> TRUE | U24: =SUM(J24+J37)='ROI Results'!J76 -> TRUE | V24: =SUM(K24+K37)='ROI Results'!K76 -> TRUE | W24: =SUM(L24+L37)='ROI Results'!L76 -> TRUE | ... Z24: =SUM(O24+O37)='ROI Results'!O76 -> TRUE
B25: Support | E25: 0 | F25: 0 | G25: 0 | H25: 0 | I25: 0 | J25: 0 | K25: 0 | L25: 0 | M25: 0 | N25: 0 | O25: =SUM(E25:N25) -> 0 | P25: =SUM(E25+E38)='ROI Results'!E77 -> TRUE | Q25: =SUM(F25+F38)='ROI Results'!F77 -> TRUE | R25: =SUM(G25+G38)='ROI Results'!G77 -> TRUE | S25: =SUM(H25+H38)='ROI Results'!H77 -> TRUE | T25: =SUM(I25+I38)='ROI Results'!I77 -> TRUE | U25: =SUM(J25+J38)='ROI Results'!J77 -> TRUE | V25: =SUM(K25+K38)='ROI Results'!K77 -> TRUE | W25: =SUM(L25+L38)='ROI Results'!L77 -> TRUE | ... Z25: =SUM(O25+O38)='ROI Results'!O77 -> TRUE
B26: Migration | E26: ='ROI Results'!E78 -> 499687.5 | F26: ='ROI Results'!F78 -> 540412.03 | G26: ='ROI Results'!G78 -> 584455.61 | H26: ='ROI Results'!H78 -> 632088.74 | I26: ='ROI Results'!I78 -> 683603.98 | J26: ='ROI Results'!J78 -> 739317.7 | K26: ='ROI Results'!K78 -> 799572.09 | L26: ='ROI Results'!L78 -> 864737.22 | ... N26: ='ROI Results'!N78 -> 1011433.2 | O26: =SUM(E26:N26) -> 7290521.4 | P26: =SUM(E26+E39)='ROI Results'!E78 -> TRUE | Q26: =SUM(F26+F39)='ROI Results'!F78 -> TRUE | R26: =SUM(G26+G39)='ROI Results'!G78 -> TRUE | S26: =SUM(H26+H39)='ROI Results'!H78 -> TRUE | T26: =SUM(I26+I39)='ROI Results'!I78 -> TRUE | U26: =SUM(J26+J39)='ROI Results'!J78 -> TRUE | V26: =SUM(K26+K39)='ROI Results'!K78 -> TRUE | W26: =SUM(L26+L39)='ROI Results'!L78 -> TRUE | ... Z26: =SUM(O26+O39)='ROI Results'!O78 -> TRUE
B27: One-time Reskilling | E27: 0 | F27: 0 | G27: 0 | H27: 0 | I27: 0 | J27: 0 | K27: 0 | L27: 0 | M27: 0 | N27: 0 | O27: =SUM(E27:N27) -> 0 | P27: =SUM(E27+E40)='ROI Results'!E79 -> TRUE | Q27: =SUM(F27+F40)='ROI Results'!F79 -> TRUE | R27: =SUM(G27+G40)='ROI Results'!G79 -> TRUE | S27: =SUM(H27+H40)='ROI Results'!H79 -> TRUE | T27: =SUM(I27+I40)='ROI Results'!I79 -> TRUE | U27: =SUM(J27+J40)='ROI Results'!J79 -> TRUE | V27: =SUM(K27+K40)='ROI Results'!K79 -> TRUE | W27: =SUM(L27+L40)='ROI Results'!L79 -> TRUE | ... Z27: =SUM(O27+O40)='ROI Results'!O79 -> TRUE
N28: Total CapEx | O28: =SUM(O19:O27) -> 56578575
E30: OpEx
B31: ='ROI Results'!$B$70 -> Ongoing current state (TCO) | E31: Year 1 | F31: Year 2 | G31: Year 3 | H31: =H$18 -> 4 | I31: =I$18 -> 5 | J31: =J$18 -> 6 | K31: =K$18 -> 7 | L31: =L$18 -> 8 | M31: =M$18 -> 9 | N31: =N$18 -> 10 | O31: Total
B32: Compute | E32: ='ROI Results'!$D71/AnalysisTerm*(1+Growth) -> 2073750 | F32: ='ROI Results'!$D71/AnalysisTerm*((1+Growth)^2)*(1+Inflation)^1 -> 2242760.6 | G32: ='ROI Results'!$D71/AnalysisTerm*((1+Growth)^3)*(1+Inflation)^2 -> 2425545.6 | H32: =IF(AnalysisTerm>3,'ROI Results'!$D71/AnalysisTerm*((1+Growth)^H$31)*(1+Inflation)^3," ") -> 2623227.6 | I32: =IF(AnalysisTerm>3,'ROI Results'!$D71/AnalysisTerm*((1+Growth)^I$31)*(1+Inflation)^H$31," ") -> 2837020.6 | J32: =IF(AnalysisTerm>$I$31,'ROI Results'!$D71/AnalysisTerm*((1+Growth)^J$31)*(1+Inflation)^I$31," ") -> 3068237.8 | K32: =IF(AnalysisTerm>$I$31,'ROI Results'!$D71/AnalysisTerm*((1+Growth)^K$31)*(1+Inflation)^J$31," ") -> 3318299.2 | L32: =IF(AnalysisTerm>$L$31,'ROI Results'!$D71/AnalysisTerm*((1+Growth)^L$31)*(1+Inflation)^K$31," ") -> 3588740.6 | M32: =IF(AnalysisTerm>$L$31,'ROI Results'!$D71/AnalysisTerm*((1+Growth)^M$31)*(1+Inflation)^L$31," ") -> 3881222.9 | N32: =IF(AnalysisTerm>$L$31,'ROI Results'!$D71/AnalysisTerm*((1+Growth)^N$31)*(1+Inflation)^M$31," ") -> 4197542.6 | O32: =SUM(E32:N32) -> 30256348
